Workbook

Sheet Resultats classement général
A4: Nom | B4: Somme de Total | C4: Somme de Hommes | D4: Somme de Femmes
A5: Marie | B5: 754 | C5: 430 | D5: 324
A6: Manon | B6: 635 | C6: 380 | D6: 255
A7: Caroline | B7: 535 | C7: 286 | D7: 249
A8: Antonin | B8: 529 | C8: 305 | D8: 224
A9: Florian | B9: 526 | C9: 352 | D9: 174
A10: Arthur | B10: 485 | C10: 280 | D10: 205
A11: Total général | B11: 3464 | C11: 2033 | D11: 1431

Sheet Resultats - Classement générale
A2: Femmes | B2: Hommes | C2: Classement | D2: Points
A3: Lou Jeanmonnot | B3: Eric Perrot | C3: 1 | D3: 90
A4: Suvi Minkinnen | B4: Tomasso Giacomel | C4: 2 | D4: 75
A5: Anna Magnusson | B5: Sebastian Samuelsson | C5: 3 | D5: 65
A6: Maren Kirkeeide | B6: Johan-Olav Botn | C6: 4 | D6: 55
A7: Hanna Oeberg | B7: Quentin Fillon Maillet | C7: 5 | D7: 50
A8: Elvira Oeberg | B8: Dale | C8: 6 | D8: 45
A9: Liza Vitozzi | B9: Ponsiluoma | C9: 7 | D9: 41
A10: Camille Bened | B10: Emilien Jacquelin | C10: 8 | D10: 37
A11: Justine Braisaz-Bouchet | B11: Christiansen | C11: 9 | D11: 34
A12: Dorothea Wierer | B12: Campbell Wright | C12: 10 | D12: 31
A13: Lou Jeanmonnot | B13: Tomasso Giacomel | C13: Sprint | D13: 50
A14: Suvi Minkinnen | B14: Eric Perrot | C14: Poursuite | D14: 50
A15: Lou Jeanmonnot | B15: Eric Perrot | C15: Individuel | D15: 50
A16: Lou Jeanmonnot | B16: Eric Perrot | C16: Mass-start | D16: 50

Sheet Pronostique
A1: Classement générale Homme
B2: 1 | C2: 2 | D2: 3 | E2: 4 | F2: 5
A3: Antonin | B3: Eric Perrot | C3: Sturla Holm Laegrid | D3: Quentin Fillon Maillet | E3: Sebastian Samuelsson | F3: Isak Frey
A4: Marie | B4: Eric Perrot | C4: Sebastian Samuelsson | D4: Sturla Holm Laegrid | E4: Quentin Fillon Maillet | F4: Tomasso Giacomel
A5: Arthur | B5: Quentin Fillon Maillet | C5: Eric Perrot | D5: Sturla Holm Laegrid | E5: Tomasso Giacomel | F5: Sebastian Samuelsson
A6: Manon | B6: Sturla Holm Laegrid | C6: Eric Perrot | D6: Quentin Fillon Maillet | E6: Sebastian Samuelsson | F6: Tomasso Giacomel
A7: Caroline | B7: Eric Perrot | C7: Sebastian Samuelsson | D7: Sturla Holm Laegrid | E7: Isak Frey | F7: Campbell Wright
A8: Florian | B8: Eric Perrot | C8: Emilien Jacquelin | D8: Tomasso Giacomel | E8: Isak Frey | F8: Sturla Holm Laegrid
A10: Classement générale Femme
B11: 1 | C11: 2 | D11: 3 | E11: 4 | F11: 5
A12: Antonin | B12: Lou Jeanmonnot | C12: Franziska Preuss | D12: Liza Vitozzi | E12: Elvira Oeberg | F12: Julia Simon
A13: Marie | B13: Lou Jeanmonnot | C13: Liza Vitozzi | D13: Franziska Preuss | E13: Jeanne Richard | F13: Elvira Oeberg
A14: Arthur | B14: Lou Jeanmonnot | C14: Liza Vitozzi | D14: Justine Braisaz-Bouchet | E14: Franziska Preuss | F14: Jeanne Richard
A15: Manon | B15: Lou Jeanmonnot | C15: Franziska Preuss | D15: Elvira Oeberg | E15: Justine Braisaz-Bouchet | F15: Liza Vitozzi
A16: Caroline | B16: Lou Jeanmonnot | C16: Liza Vitozzi | D16: Oceane Michelon | E16: Franziska Preuss | F16: Suvi Minkinnen
A17: Florian | B17: Lou Jeanmonnot | C17: Liza Vitozzi | D17: Oceane Michelon | E17: Selina Grotian | F17: Ella Halvarsson
A19: Classement petit globe Sprint
B20: Hommes | C20: Femmes
A21: Antonin | B21: Eric Perrot | C21: Franziska Preuss
A22: Marie | B22: Sturla Holm Laegrid | C22: Lou Jeanmonnot
A23: Arthur | B23: Emilien Jacquelin | C23: Justine Braisaz-Bouchet
A24: Manon | B24: Sturla Holm Laegrid | C24: Franziska Preuss
A25: Caroline | B25: Emilien Jacquelin | C25: Justine Braisaz-Bouchet
A26: Florian | B26: Sturla Holm Laegrid | C26: Liza Vitozzi
A28: Classement petit globe Poursuite
B29: Hommes | C29: Femmes
A30: Antonin | B30: Eric Perrot | C30: Lou Jeanmonnot
A31: Marie | B31: Sebastian Samuelsson | C31: Lou Jeanmonnot
A32: Arthur | B32: Sturla Holm Laegrid | C32: Julia Simon
A33: Manon | B33: Eric Perrot | C33: Lou Jeanmonnot
A34: Caroline | B34: Sebastian Samuelsson | C34: Oceane Michelon
A35: Florian | B35: Eric Perrot | C35: Lou Jeanmonnot
A37: Classement petit globe Individuel
B38: Hommes | C38: Femmes
A39: Antonin | B39: Sturla Holm Laegrid | C39: Lou Jeanmonnot
A40: Marie | B40: Eric Perrot | C40: Franziska Preuss
A41: Arthur | B41: Sturla Holm Laegrid | C41: Liza Vitozzi
A42: Manon | B42: Sturla Holm Laegrid | C42: Lou Jeanmonnot
A43: Caroline | B43: Sturla Holm Laegrid | C43: Liza Vitozzi
A44: Florian | B44: Eric Perrot | C44: Hanna Oeberg
...

Sheet Liste des candidats
A1: Hommes | B1: Femmes
A2: Eric Perrot | B2: Lou Jeanmonnot
A3: Quentin Fillon Maillet | B3: Franziska Preuss
A4: Sturla Holm Laegrid | B4: Liza Vitozzi
A5: Sebastian Samuelsson | B5: Justine Braisaz-Bouchet
A6: Emilien Jacquelin | B6: Elvira Oeberg
A7: Tomasso Giacomel | B7: Oceane Michelon
A8: Isak Frey | B8: Jeanne Richard
A9: Campbell Wright | B9: Selina Grotian
A10: Emilien Jacquelin | B10: Julia Simon
B11: Suvi Minkinnen
B12: Ella Halvarsson
B13: Hanna Oeberg

Sheet Calcul des points
A1: Classement générale Homme
B2: 1 | C2: 2 | D2: 3 | E2: 4 | F2: 5 | G2: Total
A3: Antonin | B3: =IFERROR(VLOOKUP(Pronostique!B3,'Resultats - Classement générale'!$B$3:$D$12,3,FALSE),0)+IF(Pronostique!B3='Resultats - Classement générale'!$B$3,50,0) -> 140 | C3: =IFERROR(VLOOKUP(Pronostique!C3,'Resultats - Classement générale'!$B$3:$D$12,3,FALSE),0)+IF(Pronostique!C3='Resultats - Classement générale'!$B$4,50,0) -> 0 | D3: =IFERROR(VLOOKUP(Pronostique!D3,'Resultats - Classement générale'!$B$3:$D$12,3,FALSE),0)+IF(Pronostique!D3='Resultats - Classement générale'!$B$5,50,0) -> 50 | E3: =IFERROR(VLOOKUP(Pronostique!E3,'Resultats - Classement générale'!$B$3:$D$12,3,FALSE),0)+IF(Pronostique!E3='Resultats - Classement générale'!$B$6,50,0) -> 65 | F3: =IFERROR(VLOOKUP(Pronostique!F3,'Resultats - Classement générale'!$B$3:$D$12,3,FALSE),0)+IF(Pronostique!F3='Resultats - Classement générale'!$B$7,50,0) -> 0 | G3: =SUM(B3:F3) -> 255
A4: Marie | B4: =IFERROR(VLOOKUP(Pronostique!B4,'Resultats - Classement générale'!$B$3:$D$12,3,FALSE),0)+IF(Pronostique!B4='Resultats - Classement générale'!$B$3,50,0) -> 140 | C4: =IFERROR(VLOOKUP(Pronostique!C4,'Resultats - Classement générale'!$B$3:$D$12,3,FALSE),0)+IF(Pronostique!C4='Resultats - Classement générale'!$B$4,50,0) -> 65 | D4: =IFERROR(VLOOKUP(Pronostique!D4,'Resultats - Classement générale'!$B$3:$D$12,3,FALSE),0)+IF(Pronostique!D4='Resultats - Classement générale'!$B$5,50,0) -> 0 | E4: =IFERROR(VLOOKUP(Pronostique!E4,'Resultats - Classement générale'!$B$3:$D$12,3,FALSE),0)+IF(Pronostique!E4='Resultats - Classement générale'!$B$6,50,0) -> 50 | F4: =IFERROR(VLOOKUP(Pronostique!F4,'Resultats - Classement générale'!$B$3:$D$12,3,FALSE),0)+IF(Pronostique!F4='Resultats - Classement générale'!$B$7,50,0) -> 75 | G4: =SUM(B4:F4) -> 330
A5: Arthur | B5: =IFERROR(VLOOKUP(Pronostique!B5,'Resultats - Classement générale'!$B$3:$D$12,3,FALSE),0)+IF(Pronostique!B5='Resultats - Classement générale'!$B$3,50,0) -> 50 | C5: =IFERROR(VLOOKUP(Pronostique!C5,'Resultats - Classement générale'!$B$3:$D$12,3,FALSE),0)+IF(Pronostique!C5='Resultats - Classement générale'!$B$4,50,0) -> 90 | D5: =IFERROR(VLOOKUP(Pronostique!D5,'Resultats - Classement générale'!$B$3:$D$12,3,FALSE),0)+IF(Pronostique!D5='Resultats - Classement générale'!$B$5,50,0) -> 0 | E5: =IFERROR(VLOOKUP(Pronostique!E5,'Resultats - Classement générale'!$B$3:$D$12,3,FALSE),0)+IF(Pronostique!E5='Resultats - Classement générale'!$B$6,50,0) -> 75 | F5: =IFERROR(VLOOKUP(Pronostique!F5,'Resultats - Classement générale'!$B$3:$D$12,3,FALSE),0)+IF(Pronostique!F5='Resultats - Classement générale'!$B$7,50,0) -> 65 | G5: =SUM(B5:F5) -> 280
A6: Manon | B6: =IFERROR(VLOOKUP(Pronostique!B6,'Resultats - Classement générale'!$B$3:$D$12,3,FALSE),0)+IF(Pronostique!B6='Resultats - Classement générale'!$B$3,50,0) -> 0 | C6: =IFERROR(VLOOKUP(Pronostique!C6,'Resultats - Classement générale'!$B$3:$D$12,3,FALSE),0)+IF(Pronostique!C6='Resultats - Classement générale'!$B$4,50,0) -> 90 | D6: =IFERROR(VLOOKUP(Pronostique!D6,'Resultats - Classement générale'!$B$3:$D$12,3,FALSE),0)+IF(Pronostique!D6='Resultats - Classement générale'!$B$5,50,0) -> 50 | E6: =IFERROR(VLOOKUP(Pronostique!E6,'Resultats - Classement générale'!$B$3:$D$12,3,FALSE),0)+IF(Pronostique!E6='Resultats - Classement générale'!$B$6,50,0) -> 65 | F6: =IFERROR(VLOOKUP(Pronostique!F6,'Resultats - Classement générale'!$B$3:$D$12,3,FALSE),0)+IF(Pronostique!F6='Resultats - Classement générale'!$B$7,50,0) -> 75 | G6: =SUM(B6:F6) -> 280
A7: Caroline | B7: =IFERROR(VLOOKUP(Pronostique!B7,'Resultats - Classement générale'!$B$3:$D$12,3,FALSE),0)+IF(Pronostique!B7='Resultats - Classement générale'!$B$3,50,0) -> 140 | C7: =IFERROR(VLOOKUP(Pronostique!C7,'Resultats - Classement générale'!$B$3:$D$12,3,FALSE),0)+IF(Pronostique!C7='Resultats - Classement générale'!$B$4,50,0) -> 65 | D7: =IFERROR(VLOOKUP(Pronostique!D7,'Resultats - Classement générale'!$B$3:$D$12,3,FALSE),0)+IF(Pronostique!D7='Resultats - Classement générale'!$B$5,50,0) -> 0 | E7: =IFERROR(VLOOKUP(Pronostique!E7,'Resultats - Classement générale'!$B$3:$D$12,3,FALSE),0)+IF(Pronostique!E7='Resultats - Classement générale'!$B$6,50,0) -> 0 | F7: =IFERROR(VLOOKUP(Pronostique!F7,'Resultats - Classement générale'!$B$3:$D$12,3,FALSE),0)+IF(Pronostique!F7='Resultats - Classement générale'!$B$7,50,0) -> 31 | G7: =SUM(B7:F7) -> 236
A8: Florian | B8: =IFERROR(VLOOKUP(Pronostique!B8,'Resultats - Classement générale'!$B$3:$D$12,3,FALSE),0)+IF(Pronostique!B8='Resultats - Classement générale'!$B$3,50,0) -> 140 | C8: =IFERROR(VLOOKUP(Pronostique!C8,'Resultats - Classement générale'!$B$3:$D$12,3,FALSE),0)+IF(Pronostique!C8='Resultats - Classement générale'!$B$4,50,0) -> 37 | D8: =IFERROR(VLOOKUP(Pronostique!D8,'Resultats - Classement générale'!$B$3:$D$12,3,FALSE),0)+IF(Pronostique!D8='Resultats - Classement générale'!$B$5,50,0) -> 75 | E8: =IFERROR(VLOOKUP(Pronostique!E8,'Resultats - Classement générale'!$B$3:$D$12,3,FALSE),0)+IF(Pronostique!E8='Resultats - Classement générale'!$B$6,50,0) -> 0 | F8: =IFERROR(VLOOKUP(Pronostique!F8,'Resultats - Classement générale'!$B$3:$D$12,3,FALSE),0)+IF(Pronostique!F8='Resultats - Classement générale'!$B$7,50,0) -> 0 | G8: =SUM(B8:F8) -> 252
A10: Classement générale Femme
B11: 1 | C11: 2 | D11: 3 | E11: 4 | F11: 5 | G11: Total
A12: Antonin | B12: =IFERROR(VLOOKUP(Pronostique!B12,'Resultats - Classement générale'!$A$3:$D$12,4,FALSE),0)+IF(Pronostique!B12='Resultats - Classement générale'!$A$3,50,0) -> 140 | C12: =IFERROR(VLOOKUP(Pronostique!C12,'Resultats - Classement générale'!$A$3:$D$12,4,FALSE),0)+IF(Pronostique!C12='Resultats - Classement générale'!$A$4,50,0) -> 0 | D12: =IFERROR(VLOOKUP(Pronostique!D12,'Resultats - Classement générale'!$A$3:$D$12,4,FALSE),0)+IF(Pronostique!D12='Resultats - Classement générale'!$A$5,50,0) -> 41 | E12: =IFERROR(VLOOKUP(Pronostique!E12,'Resultats - Classement générale'!$A$3:$D$12,4,FALSE),0)+IF(Pronostique!E12='Resultats - Classement générale'!$A$6,50,0) -> 45 | F12: =IFERROR(VLOOKUP(Pronostique!F12,'Resultats - Classement générale'!$A$3:$D$12,4,FALSE),0)+IF(Pronostique!F12='Resultats - Classement générale'!$A$7,50,0) -> 0 | G12: =SUM(B12:F12) -> 226
A13: Marie | B13: =IFERROR(VLOOKUP(Pronostique!B13,'Resultats - Classement générale'!$A$3:$D$12,4,FALSE),0)+IF(Pronostique!B13='Resultats - Classement générale'!$A$3,50,0) -> 140 | C13: =IFERROR(VLOOKUP(Pronostique!C13,'Resultats - Classement générale'!$A$3:$D$12,4,FALSE),0)+IF(Pronostique!C13='Resultats - Classement générale'!$A$4,50,0) -> 41 | D13: =IFERROR(VLOOKUP(Pronostique!D13,'Resultats - Classement générale'!$A$3:$D$12,4,FALSE),0)+IF(Pronostique!D13='Resultats - Classement générale'!$A$5,50,0) -> 0 | E13: =IFERROR(VLOOKUP(Pronostique!E13,'Resultats - Classement générale'!$A$3:$D$12,4,FALSE),0)+IF(Pronostique!E13='Resultats - Classement générale'!$A$6,50,0) -> 0 | F13: =IFERROR(VLOOKUP(Pronostique!F13,'Resultats - Classement générale'!$A$3:$D$12,4,FALSE),0)+IF(Pronostique!F13='Resultats - Classement générale'!$A$7,50,0) -> 45 | G13: =SUM(B13:F13) -> 226
A14: Arthur | B14: =IFERROR(VLOOKUP(Pronostique!B14,'Resultats - Classement générale'!$A$3:$D$12,4,FALSE),0)+IF(Pronostique!B14='Resultats - Classement générale'!$A$3,50,0) -> 140 | C14: =IFERROR(VLOOKUP(Pronostique!C14,'Resultats - Classement générale'!$A$3:$D$12,4,FALSE),0)+IF(Pronostique!C14='Resultats - Classement générale'!$A$4,50,0) -> 41 | D14: =IFERROR(VLOOKUP(Pronostique!D14,'Resultats - Classement générale'!$A$3:$D$12,4,FALSE),0)+IF(Pronostique!D14='Resultats - Classement générale'!$A$5,50,0) -> 34 | E14: =IFERROR(VLOOKUP(Pronostique!E14,'Resultats - Classement générale'!$A$3:$D$12,4,FALSE),0)+IF(Pronostique!E14='Resultats - Classement générale'!$A$6,50,0) -> 0 | F14: =IFERROR(VLOOKUP(Pronostique!F14,'Resultats - Classement générale'!$A$3:$D$12,4,FALSE),0)+IF(Pronostique!F14='Resultats - Classement générale'!$A$7,50,0) -> 0 | G14: =SUM(B14:F14) -> 215
A15: Manon | B15: =IFERROR(VLOOKUP(Pronostique!B15,'Resultats - Classement générale'!$A$3:$D$12,4,FALSE),0)+IF(Pronostique!B15='Resultats - Classement générale'!$A$3,50,0) -> 140 | C15: =IFERROR(VLOOKUP(Pronostique!C15,'Resultats - Classement générale'!$A$3:$D$12,4,FALSE),0)+IF(Pronostique!C15='Resultats - Classement générale'!$A$4,50,0) -> 0 | D15: =IFERROR(VLOOKUP(Pronostique!D15,'Resultats - Classement générale'!$A$3:$D$12,4,FALSE),0)+IF(Pronostique!D15='Resultats - Classement générale'!$A$5,50,0) -> 45 | E15: =IFERROR(VLOOKUP(Pronostique!E15,'Resultats - Classement générale'!$A$3:$D$12,4,FALSE),0)+IF(Pronostique!E15='Resultats - Classement générale'!$A$6,50,0) -> 34 | F15: =IFERROR(VLOOKUP(Pronostique!F15,'Resultats - Classement générale'!$A$3:$D$12,4,FALSE),0)+IF(Pronostique!F15='Resultats - Classement générale'!$A$7,50,0) -> 41 | G15: =SUM(B15:F15) -> 260
A16: Caroline | B16: =IFERROR(VLOOKUP(Pronostique!B16,'Resultats - Classement générale'!$A$3:$D$12,4,FALSE),0)+IF(Pronostique!B16='Resultats - Classement générale'!$A$3,50,0) -> 140 | C16: =IFERROR(VLOOKUP(Pronostique!C16,'Resultats - Classement générale'!$A$3:$D$12,4,FALSE),0)+IF(Pronostique!C16='Resultats - Classement générale'!$A$4,50,0) -> 41 | D16: =IFERROR(VLOOKUP(Pronostique!D16,'Resultats - Classement générale'!$A$3:$D$12,4,FALSE),0)+IF(Pronostique!D16='Resultats - Classement générale'!$A$5,50,0) -> 0 | E16: =IFERROR(VLOOKUP(Pronostique!E16,'Resultats - Classement générale'!$A$3:$D$12,4,FALSE),0)+IF(Pronostique!E16='Resultats - Classement générale'!$A$6,50,0) -> 0 | F16: =IFERROR(VLOOKUP(Pronostique!F16,'Resultats - Classement générale'!$A$3:$D$12,4,FALSE),0)+IF(Pronostique!F16='Resultats - Classement générale'!$A$7,50,0) -> 75 | G16: =SUM(B16:F16) -> 256
A17: Florian | B17: =IFERROR(VLOOKUP(Pronostique!B17,'Resultats - Classement générale'!$A$3:$D$12,4,FALSE),0)+IF(Pronostique!B17='Resultats - Classement générale'!$A$3,50,0) -> 140 | C17: =IFERROR(VLOOKUP(Pronostique!C17,'Resultats - Classement générale'!$A$3:$D$12,4,FALSE),0)+IF(Pronostique!C17='Resultats - Classement générale'!$A$4,50,0) -> 41 | D17: =IFERROR(VLOOKUP(Pronostique!D17,'Resultats - Classement générale'!$A$3:$D$12,4,FALSE),0)+IF(Pronostique!D17='Resultats - Classement générale'!$A$5,50,0) -> 0 | E17: =IFERROR(VLOOKUP(Pronostique!E17,'Resultats - Classement générale'!$A$3:$D$12,4,FALSE),0)+IF(Pronostique!E17='Resultats - Classement générale'!$A$6,50,0) -> 0 | F17: =IFERROR(VLOOKUP(Pronostique!F17,'Resultats - Classement générale'!$A$3:$D$12,4,FALSE),0)+IF(Pronostique!F17='Resultats - Classement générale'!$A$7,50,0) -> 0 | G17: =SUM(B17:F17) -> 181
A19: Classement petit globe Sprint
B20: Hommes | C20: Femmes
A21: Antonin | B21: =IF(Pronostique!B21='Resultats - Classement générale'!$B$13,50,0) -> 0 | C21: =IF(Pronostique!C21='Resultats - Classement générale'!$A$13,50,0) -> 0
A22: Marie | B22: =IF(Pronostique!B22='Resultats - Classement générale'!$B$13,50,0) -> 0 | C22: =IF(Pronostique!C22='Resultats - Classement générale'!$A$13,50,0) -> 50
A23: Arthur | B23: =IF(Pronostique!B23='Resultats - Classement générale'!$B$13,50,0) -> 0 | C23: =IF(Pronostique!C23='Resultats - Classement générale'!$A$13,50,0) -> 0
A24: Manon | B24: =IF(Pronostique!B24='Resultats - Classement générale'!$B$13,50,0) -> 0 | C24: =IF(Pronostique!C24='Resultats - Classement générale'!$A$13,50,0) -> 0
A25: Caroline | B25: =IF(Pronostique!B25='Resultats - Classement générale'!$B$13,50,0) -> 0 | C25: =IF(Pronostique!C25='Resultats - Classement générale'!$A$13,50,0) -> 0
A26: Florian | B26: =IF(Pronostique!B26='Resultats - Classement générale'!$B$13,50,0) -> 0 | C26: =IF(Pronostique!C26='Resultats - Classement générale'!$A$13,50,0) -> 0
A28: Classement petit globe Poursuite
B29: Hommes | C29: Femmes
A30: Antonin | B30: =IF(Pronostique!B30='Resultats - Classement générale'!$B$14,50,0) -> 50 | C30: =IF(Pronostique!C30='Resultats - Classement générale'!$A$14,50,0) -> 0
A31: Marie | B31: =IF(Pronostique!B31='Resultats - Classement générale'!$B$14,50,0) -> 0 | C31: =IF(Pronostique!C31='Resultats - Classement générale'!$A$14,50,0) -> 0
A32: Arthur | B32: =IF(Pronostique!B32='Resultats - Classement générale'!$B$14,50,0) -> 0 | C32: =IF(Pronostique!C32='Resultats - Classement générale'!$A$14,50,0) -> 0
A33: Manon | B33: =IF(Pronostique!B33='Resultats - Classement générale'!$B$14,50,0) -> 50 | C33: =IF(Pronostique!C33='Resultats - Classement générale'!$A$14,50,0) -> 0
A34: Caroline | B34: =IF(Pronostique!B34='Resultats - Classement générale'!$B$14,50,0) -> 0 | C34: =IF(Pronostique!C34='Resultats - Classement générale'!$A$14,50,0) -> 0
A35: Florian | B35: =IF(Pronostique!B35='Resultats - Classement générale'!$B$14,50,0) -> 50 | C35: =IF(Pronostique!C35='Resultats - Classement générale'!$A$14,50,0) -> 0
A37: Classement petit globe Individuel
B38: Hommes | C38: Femmes
A39: Antonin | B39: =IF(Pronostique!B39='Resultats - Classement générale'!$B$15,50,0) -> 0 | C39: =IF(Pronostique!C39='Resultats - Classement générale'!$A$15,50,0) -> 50
A40: Marie | B40: =IF(Pronostique!B40='Resultats - Classement générale'!$B$15,50,0) -> 50 | C40: =IF(Pronostique!C40='Resultats - Classement générale'!$A$15,50,0) -> 0
A41: Arthur | B41: =IF(Pronostique!B41='Resultats - Classement générale'!$B$15,50,0) -> 0 | C41: =IF(Pronostique!C41='Resultats - Classement générale'!$A$15,50,0) -> 0
A42: Manon | B42: =IF(Pronostique!B42='Resultats - Classement générale'!$B$15,50,0) -> 0 | C42: =IF(Pronostique!C42='Resultats - Classement générale'!$A$15,50,0) -> 50
A43: Caroline | B43: =IF(Pronostique!B43='Resultats - Classement générale'!$B$15,50,0) -> 0 | C43: =IF(Pronostique!C43='Resultats - Classement générale'!$A$15,50,0) -> 0
A44: Florian | B44: =IF(Pronostique!B44='Resultats - Classement générale'!$B$15,50,0) -> 50 | C44: =IF(Pronostique!C44='Resultats - Classement générale'!$A$15,50,0) -> 0
...
